Workbook

Sheet Dashboard
A1: Dashboard — Mesa de Regalos
A2: Todos los datos se recalculan automáticamente desde las hojas de captura.
A4: Ingresos por sucursal | D4: Ventas por rango de precio
A5: Sucursal | B5: Ingreso | D5: Rango | E5: Ingreso
A6: Garita | B6: =SUMIF(Mesas[Sucursal],$A6,Mesas[Ingreso real generado]) | D6: $100-300 | E6: =SUMIFS(Productos[Precio],Productos[Rango de precio],$D6,Productos[Estado],"Vendido")
A7: Buen Tono | B7: =SUMIF(Mesas[Sucursal],$A7,Mesas[Ingreso real generado]) | D7: $300-600 | E7: =SUMIFS(Productos[Precio],Productos[Rango de precio],$D7,Productos[Estado],"Vendido")
A8: La Gracia | B8: =SUMIF(Mesas[Sucursal],$A8,Mesas[Ingreso real generado]) | D8: $600-1000 | E8: =SUMIFS(Productos[Precio],Productos[Rango de precio],$D8,Productos[Estado],"Vendido")
A9: San Borja | B9: =SUMIF(Mesas[Sucursal],$A9,Mesas[Ingreso real generado]) | D9: $1000+ | E9: =SUMIFS(Productos[Precio],Productos[Rango de precio],$D9,Productos[Estado],"Vendido")
A11: Ingresos por mes (año actual de la Hoja 3) | D11: Tasa de conversión por sucursal
A12: Mes | B12: Ingreso | D12: Sucursal | E12: Conversión
A13: =DATE('Ingresos por Sucursal y Mes'!$B$2,1,1) | B13: ='Ingresos por Sucursal y Mes'!B9 | D13: Garita | E13: =IFERROR(SUMIF(Mesas[Sucursal],$D13,Mesas[# de productos vendidos])/SUMIF(Mesas[Sucursal],$D13,Mesas[# de productos en la lista]),0)
A14: =DATE('Ingresos por Sucursal y Mes'!$B$2,2,1) | B14: ='Ingresos por Sucursal y Mes'!C9 | D14: Buen Tono | E14: =IFERROR(SUMIF(Mesas[Sucursal],$D14,Mesas[# de productos vendidos])/SUMIF(Mesas[Sucursal],$D14,Mesas[# de productos en la lista]),0)
A15: =DATE('Ingresos por Sucursal y Mes'!$B$2,3,1) | B15: ='Ingresos por Sucursal y Mes'!D9 | D15: La Gracia | E15: =IFERROR(SUMIF(Mesas[Sucursal],$D15,Mesas[# de productos vendidos])/SUMIF(Mesas[Sucursal],$D15,Mesas[# de productos en la lista]),0)
A16: =DATE('Ingresos por Sucursal y Mes'!$B$2,4,1) | B16: ='Ingresos por Sucursal y Mes'!E9 | D16: San Borja | E16: =IFERROR(SUMIF(Mesas[Sucursal],$D16,Mesas[# de productos vendidos])/SUMIF(Mesas[Sucursal],$D16,Mesas[# de productos en la lista]),0)
A17: =DATE('Ingresos por Sucursal y Mes'!$B$2,5,1) | B17: ='Ingresos por Sucursal y Mes'!F9
A18: =DATE('Ingresos por Sucursal y Mes'!$B$2,6,1) | B18: ='Ingresos por Sucursal y Mes'!G9
A19: =DATE('Ingresos por Sucursal y Mes'!$B$2,7,1) | B19: ='Ingresos por Sucursal y Mes'!H9
A20: =DATE('Ingresos por Sucursal y Mes'!$B$2,8,1) | B20: ='Ingresos por Sucursal y Mes'!I9
A21: =DATE('Ingresos por Sucursal y Mes'!$B$2,9,1) | B21: ='Ingresos por Sucursal y Mes'!J9
A22: =DATE('Ingresos por Sucursal y Mes'!$B$2,10,1) | B22: ='Ingresos por Sucursal y Mes'!K9
A23: =DATE('Ingresos por Sucursal y Mes'!$B$2,11,1) | B23: ='Ingresos por Sucursal y Mes'!L9
A24: =DATE('Ingresos por Sucursal y Mes'!$B$2,12,1) | B24: ='Ingresos por Sucursal y Mes'!M9

Sheet Mesas Registradas
A1: Mesa de Regalos — Registro de mesas
A2: Captura una fila por cada mesa registrada. Las columnas azul claro son de captura manual. Las columnas verde claro se calculan automáticamente desde la hoja 'Detalle de Productos por Mesa'. Puedes agregar filas al final de la tabla y las fórmulas se copiarán solas. Borra las filas marcadas 'EJEMPLO — BORRAR' antes de usar el archivo en producción.
A4: ID de mesa | B4: Sucursal | C4: Nombre del festejado | D4: Fecha de registro | E4: Fecha del evento | F4: Edad | G4: # de productos en la lista | H4: Valor total de la lista | I4: # de productos vendidos | J4: Ingreso real generado | K4: % de la lista vendida | L4: Fecha de cierre de la mesa
A5: M001 | B5: Garita | C5: EJEMPLO — Sofía López (BORRAR) | D5: 46037 | E5: 46073 | F5: 5 | G5: =COUNTIF(Productos[ID de mesa],[@[ID de mesa]]) | H5: =SUMIFS(Productos[Precio],Productos[ID de mesa],[@[ID de mesa]]) | I5: =COUNTIFS(Productos[ID de mesa],[@[ID de mesa]],Productos[Estado],"Vendido") | J5: =SUMIFS(Productos[Precio],Productos[ID de mesa],[@[ID de mesa]],Productos[Estado],"Vendido") | K5: =IFERROR([@[# de productos vendidos]]/[@[# de productos en la lista]],0) | L5: 46078
A6: M002 | B6: Buen Tono | C6: EJEMPLO — Diego Ramírez (BORRAR) | D6: 46056 | E6: 46091 | F6: 7 | G6: =COUNTIF(Productos[ID de mesa],[@[ID de mesa]]) | H6: =SUMIFS(Productos[Precio],Productos[ID de mesa],[@[ID de mesa]]) | I6: =COUNTIFS(Productos[ID de mesa],[@[ID de mesa]],Productos[Estado],"Vendido") | J6: =SUMIFS(Productos[Precio],Productos[ID de mesa],[@[ID de mesa]],Productos[Estado],"Vendido") | K6: =IFERROR([@[# de productos vendidos]]/[@[# de productos en la lista]],0) | L6: 46096
A7: M003 | B7: La Gracia | C7: EJEMPLO — Valentina Ruiz (BORRAR) | D7: 46073 | E7: 46117 | F7: 3 | G7: =COUNTIF(Productos[ID de mesa],[@[ID de mesa]]) | H7: =SUMIFS(Productos[Precio],Productos[ID de mesa],[@[ID de mesa]]) | I7: =COUNTIFS(Productos[ID de mesa],[@[ID de mesa]],Productos[Estado],"Vendido") | J7: =SUMIFS(Productos[Precio],Productos[ID de mesa],[@[ID de mesa]],Productos[Estado],"Vendido") | K7: =IFERROR([@[# de productos vendidos]]/[@[# de productos en la lista]],0) | L7: 46122
A8: M004 | B8: San Borja | C8: EJEMPLO — Mateo Herrera (BORRAR) | D8: 46089 | E8: 46127 | F8: 8 | G8: =COUNTIF(Productos[ID de mesa],[@[ID de mesa]]) | H8: =SUMIFS(Productos[Precio],Productos[ID de mesa],[@[ID de mesa]]) | I8: =COUNTIFS(Productos[ID de mesa],[@[ID de mesa]],Productos[Estado],"Vendido") | J8: =SUMIFS(Productos[Precio],Productos[ID de mesa],[@[ID de mesa]],Productos[Estado],"Vendido") | K8: =IFERROR([@[# de productos vendidos]]/[@[# de productos en la lista]],0) | L8: 46132
A9: M005 | B9: Garita | C9: EJEMPLO — Camila Torres (BORRAR) | D9: 46124 | E9: 46167 | F9: 6 | G9: =COUNTIF(Productos[ID de mesa],[@[ID de mesa]]) | H9: =SUMIFS(Productos[Precio],Productos[ID de mesa],[@[ID de mesa]]) | I9: =COUNTIFS(Productos[ID de mesa],[@[ID de mesa]],Productos[Estado],"Vendido") | J9: =SUMIFS(Productos[Precio],Productos[ID de mesa],[@[ID de mesa]],Productos[Estado],"Vendido") | K9: =IFERROR([@[# de productos vendidos]]/[@[# de productos en la lista]],0) | L9: 46172
A10: M006 | B10: Buen Tono | C10: EJEMPLO — Emiliano Cruz (BORRAR) | D10: 46147 | E10: 46185 | F10: 4 | G10: =COUNTIF(Productos[ID de mesa],[@[ID de mesa]]) | H10: =SUMIFS(Productos[Precio],Productos[ID de mesa],[@[ID de mesa]]) | I10: =COUNTIFS(Productos[ID de mesa],[@[ID de mesa]],Productos[Estado],"Vendido") | J10: =SUMIFS(Productos[Precio],Productos[ID de mesa],[@[ID de mesa]],Productos[Estado],"Vendido") | K10: =IFERROR([@[# de productos vendidos]]/[@[# de productos en la lista]],0) | L10: 46188
A11: M007 | B11: La Gracia | C11: EJEMPLO — Regina Vega (BORRAR) | D11: 46183 | E11: 46223 | F11: 9 | G11: =COUNTIF(Productos[ID de mesa],[@[ID de mesa]]) | H11: =SUMIFS(Productos[Precio],Productos[ID de mesa],[@[ID de mesa]]) | I11: =COUNTIFS(Productos[ID de mesa],[@[ID de mesa]],Productos[Estado],"Vendido") | J11: =SUMIFS(Productos[Precio],Productos[ID de mesa],[@[ID de mesa]],Productos[Estado],"Vendido") | K11: =IFERROR([@[# de productos vendidos]]/[@[# de productos en la lista]],0) | L11: 46228
A12: M008 | B12: San Borja | C12: EJEMPLO — Santiago Ríos (BORRAR) | D12: 46204 | E12: 46242 | F12: 2 | G12: =COUNTIF(Productos[ID de mesa],[@[ID de mesa]]) | H12: =SUMIFS(Productos[Precio],Productos[ID de mesa],[@[ID de mesa]]) | I12: =COUNTIFS(Productos[ID de mesa],[@[ID de mesa]],Productos[Estado],"Vendido") | J12: =SUMIFS(Productos[Precio],Productos[ID de mesa],[@[ID de mesa]],Productos[Estado],"Vendido") | K12: =IFERROR([@[# de productos vendidos]]/[@[# de productos en la lista]],0)
A13: M009 | B13: Garita | C13: EJEMPLO — Isabella Núñez (BORRAR) | D13: 46221 | E13: 46262 | F13: 10 | G13: =COUNTIF(Productos[ID de mesa],[@[ID de mesa]]) | H13: =SUMIFS(Productos[Precio],Productos[ID de mesa],[@[ID de mesa]]) | I13: =COUNTIFS(Productos[ID de mesa],[@[ID de mesa]],Productos[Estado],"Vendido") | J13: =SUMIFS(Productos[Precio],Productos[ID de mesa],[@[ID de mesa]],Productos[Estado],"Vendido") | K13: =IFERROR([@[# de productos vendidos]]/[@[# de productos en la lista]],0)
A14: M010 | B14: Buen Tono | C14: EJEMPLO — Leonardo Ávila (BORRAR) | D14: 46239 | E14: 46280 | F14: 5 | G14: =COUNTIF(Productos[ID de mesa],[@[ID de mesa]]) | H14: =SUMIFS(Productos[Precio],Productos[ID de mesa],[@[ID de mesa]]) | I14: =COUNTIFS(Productos[ID de mesa],[@[ID de mesa]],Productos[Estado],"Vendido") | J14: =SUMIFS(Productos[Precio],Productos[ID de mesa],[@[ID de mesa]],Productos[Estado],"Vendido") | K14: =IFERROR([@[# de productos vendidos]]/[@[# de productos en la lista]],0)

Sheet Detalle de Productos por Mesa
A1: Mesa de Regalos — Detalle de productos por mesa
A2: Captura una fila por producto asociado a cada mesa. El 'Rango de precio' se calcula automáticamente. Al marcar 'Estado' = 'Vendido', el ingreso y la conversión de la mesa correspondiente se actualizan solos. Puedes agregar filas al final; las fórmulas y la validación se copian solas.
A4: ID de mesa | B4: Producto | C4: Precio | D4: Rango de precio | E4: Estado | F4: Fecha de venta | G4: Fue sugerencia fuera de lista
A5: M001 | B5: Muñeca Baby Alive | C5: 850 | D5: =IF([@Precio]="","",IF([@Precio]<300,"$100-300",IF([@Precio]<600,"$300-600",IF([@Precio]<1000,"$600-1000","$1000+")))) | E5: Vendido | F5: 46071 | G5: No
A6: M001 | B6: Set de bloques LEGO Classic | C6: 650 | D6: =IF([@Precio]="","",IF([@Precio]<300,"$100-300",IF([@Precio]<600,"$300-600",IF([@Precio]<1000,"$600-1000","$1000+")))) | E6: Vendido | F6: 46072 | G6: No
A7: M001 | B7: Peluche Unicornio grande | C7: 420 | D7: =IF([@Precio]="","",IF([@Precio]<300,"$100-300",IF([@Precio]<600,"$300-600",IF([@Precio]<1000,"$600-1000","$1000+")))) | E7: Vendido | F7: 46068 | G7: No
A8: M001 | B8: Kit de arte Crayola | C8: 280 | D8: =IF([@Precio]="","",IF([@Precio]<300,"$100-300",IF([@Precio]<600,"$300-600",IF([@Precio]<1000,"$600-1000","$1000+")))) | E8: Disponible | G8: No
A9: M001 | B9: Bicicleta rodada 12 | C9: 1450 | D9: =IF([@Precio]="","",IF([@Precio]<300,"$100-300",IF([@Precio]<600,"$300-600",IF([@Precio]<1000,"$600-1000","$1000+")))) | E9: Disponible | G9: No
A10: M002 | B10: Set cocina de juguete | C10: 990 | D10: =IF([@Precio]="","",IF([@Precio]<300,"$100-300",IF([@Precio]<600,"$300-600",IF([@Precio]<1000,"$600-1000","$1000+")))) | E10: Vendido | F10: 46086 | G10: No
A11: M002 | B11: Rompecabezas 500 pzs | C11: 320 | D11: =IF([@Precio]="","",IF([@Precio]<300,"$100-300",IF([@Precio]<600,"$300-600",IF([@Precio]<1000,"$600-1000","$1000+")))) | E11: Vendido | F11: 46088 | G11: No
A12: M002 | B12: Nerf Elite Blaster | C12: 580 | D12: =IF([@Precio]="","",IF([@Precio]<300,"$100-300",IF([@Precio]<600,"$300-600",IF([@Precio]<1000,"$600-1000","$1000+")))) | E12: Vendido | F12: 46089 | G12: Sí
A13: M002 | B13: Set Play-Doh 10 colores | C13: 190 | D13: =IF([@Precio]="","",IF([@Precio]<300,"$100-300",IF([@Precio]<600,"$300-600",IF([@Precio]<1000,"$600-1000","$1000+")))) | E13: Vendido | F13: 46085 | G13: No
A14: M002 | B14: Patineta iniciación | C14: 1290 | D14: =IF([@Precio]="","",IF([@Precio]<300,"$100-300",IF([@Precio]<600,"$300-600",IF([@Precio]<1000,"$600-1000","$1000+")))) | E14: Vendido | F14: 46090 | G14: No
A15: M002 | B15: Muñeco superhéroe | C15: 450 | D15: =IF([@Precio]="","",IF([@Precio]<300,"$100-300",IF([@Precio]<600,"$300-600",IF([@Precio]<1000,"$600-1000","$1000+")))) | E15: Disponible | G15: No
A16: M002 | B16: Libro para colorear XL | C16: 140 | D16: =IF([@Precio]="","",IF([@Precio]<300,"$100-300",IF([@Precio]<600,"$300-600",IF([@Precio]<1000,"$600-1000","$1000+")))) | E16: Vendido | F16: 46087 | G16: No
A17: M003 | B17: Auto a control remoto | C17: 890 | D17: =IF([@Precio]="","",IF([@Precio]<300,"$100-300",IF([@Precio]<600,"$300-600",IF([@Precio]<1000,"$600-1000","$1000+")))) | E17: Vendido | F17: 46114 | G17: No
A18: M003 | B18: Set experimentos ciencia | C18: 690 | D18: =IF([@Precio]="","",IF([@Precio]<300,"$100-300",IF([@Precio]<600,"$300-600",IF([@Precio]<1000,"$600-1000","$1000+")))) | E18: Vendido | F18: 46115 | G18: No
A19: M003 | B19: Muñeca Barbie | C19: 550 | D19: =IF([@Precio]="","",IF([@Precio]<300,"$100-300",IF([@Precio]<600,"$300-600",IF([@Precio]<1000,"$600-1000","$1000+")))) | E19: Disponible | G19: No
A20: M004 | B20: Consola portátil educativa | C20: 1890 | D20: =IF([@Precio]="","",IF([@Precio]<300,"$100-300",IF([@Precio]<600,"$300-600",IF([@Precio]<1000,"$600-1000","$1000+")))) | E20: Vendido | F20: 46124 | G20: No
A21: M004 | B21: Set 6 dinosaurios grandes | C21: 720 | D21: =IF([@Precio]="","",IF([@Precio]<300,"$100-300",IF([@Precio]<600,"$300-600",IF([@Precio]<1000,"$600-1000","$1000+")))) | E21: Vendido | F21: 46122 | G21: No
A22: M004 | B22: Pista Hot Wheels | C22: 620 | D22: =IF([@Precio]="","",IF([@Precio]<300,"$100-300",IF([@Precio]<600,"$300-600",IF([@Precio]<1000,"$600-1000","$1000+")))) | E22: Vendido | F22: 46123 | G22: No
A23: M004 | B23: Cubo Rubik pro | C23: 350 | D23: =IF([@Precio]="","",IF([@Precio]<300,"$100-300",IF([@Precio]<600,"$300-600",IF([@Precio]<1000,"$600-1000","$1000+")))) | E23: Vendido | F23: 46125 | G23: No
A24: M004 | B24: Set slime | C24: 180 | D24: =IF([@Precio]="","",IF([@Precio]<300,"$100-300",IF([@Precio]<600,"$300-600",IF([@Precio]<1000,"$600-1000","$1000+")))) | E24: Vendido | F24: 46121 | G24: No
A25: M004 | B25: Peluche osito | C25: 240 | D25: =IF([@Precio]="","",IF([@Precio]<300,"$100-300",IF([@Precio]<600,"$300-600",IF([@Precio]<1000,"$600-1000","$1000+")))) | E25: Disponible | G25: No
A26: M004 | B26: Juego de mesa Monopoly | C26: 520 | D26: =IF([@Precio]="","",IF([@Precio]<300,"$100-300",IF([@Precio]<600,"$300-600",IF([@Precio]<1000,"$600-1000","$1000+")))) | E26: Vendido | F26: 46126 | G26: Sí
A27: M004 | B27: Balón fútbol No.5 | C27: 290 | D27: =IF([@Precio]="","",IF([@Precio]<300,"$100-300",IF([@Precio]<600,"$300-600",IF([@Precio]<1000,"$600-1000","$1000+")))) | E27: Disponible | G27: No
A28: M005 | B28: Casita muñecas plegable | C28: 1650 | D28: =IF([@Precio]="","",IF([@Precio]<300,"$100-300",IF([@Precio]<600,"$300-600",IF([@Precio]<1000,"$600-1000","$1000+")))) | E28: Vendido | F28: 46162 | G28: No
A29: M005 | B29: Set de té porcelana | C29: 380 | D29: =IF([@Precio]="","",IF([@Precio]<300,"$100-300",IF([@Precio]<600,"$300-600",IF([@Precio]<1000,"$600-1000","$1000+")))) | E29: Vendido | F29: 46164 | G29: No
A30: M005 | B30: Pulseras DIY | C30: 220 | D30: =IF([@Precio]="","",IF([@Precio]<300,"$100-300",IF([@Precio]<600,"$300-600",IF([@Precio]<1000,"$600-1000","$1000+")))) | E30: Disponible | G30: No
A31: M005 | B31: Peluche mediano | C31: 310 | D31: =IF([@Precio]="","",IF([@Precio]<300,"$100-300",IF([@Precio]<600,"$300-600",IF([@Precio]<1000,"$600-1000","$1000+")))) | E31: Vendido | F31: 46160 | G31: No
A32: M005 | B32: Libro cuentos infantiles | C32: 150 | D32: =IF([@Precio]="","",IF([@Precio]<300,"$100-300",IF([@Precio]<600,"$300-600",IF([@Precio]<1000,"$600-1000","$1000+")))) | E32: Disponible | G32: No
A33: M005 | B33: Muñeca articulada | C33: 580 | D33: =IF([@Precio]="","",IF([@Precio]<300,"$100-300",IF([@Precio]<600,"$300-600",IF([@Precio]<1000,"$600-1000","$1000+")))) | E33: Vendido | F33: 46167 | G33: No
A34: M006 | B34: Scooter rodada 16 | C34: 1750 | D34: =IF([@Precio]="","",IF([@Precio]<300,"$100-300",IF([@Precio]<600,"$300-600",IF([@Precio]<1000,"$600-1000","$1000+")))) | E34: Vendido | F34: 46183 | G34: No
A35: M006 | B35: Set carritos die-cast | C35: 480 | D35: =IF([@Precio]="","",IF([@Precio]<300,"$100-300",IF([@Precio]<600,"$300-600",IF([@Precio]<1000,"$600-1000","$1000+")))) | E35: Vendido | F35: 46181 | G35: No
A36: M006 | B36: Juego memoria | C36: 210 | D36: =IF([@Precio]="","",IF([@Precio]<300,"$100-300",IF([@Precio]<600,"$300-600",IF([@Precio]<1000,"$600-1000","$1000+")))) | E36: Vendido | F36: 46182 | G36: No
A37: M006 | B37: Robot armable STEM | C37: 890 | D37: =IF([@Precio]="","",IF([@Precio]<300,"$100-300",IF([@Precio]<600,"$300-600",IF([@Precio]<1000,"$600-1000","$1000+")))) | E37: Disponible | G37: No
A38: M007 | B38: Piano infantil | C38: 980 | D38: =IF([@Precio]="","",IF([@Precio]<300,"$100-300",IF([@Precio]<600,"$300-600",IF([@Precio]<1000,"$600-1000","$1000+")))) | E38: Vendido | F38: 46218 | G38: No
A39: M007 | B39: Set 20 pinturas acrílicas | C39: 340 | D39: =IF([@Precio]="","",IF([@Precio]<300,"$100-300",IF([@Precio]<600,"$300-600",IF([@Precio]<1000,"$600-1000","$1000+")))) | E39: Disponible | G39: No
A40: M007 | B40: Muñeca LOL Surprise | C40: 520 | D40: =IF([@Precio]="","",IF([@Precio]<300,"$100-300",IF([@Precio]<600,"$300-600",IF([@Precio]<1000,"$600-1000","$1000+")))) | E40: Vendido | F40: 46221 | G40: No
A41: M007 | B41: Nintendo Switch Lite | C41: 5500 | D41: =IF([@Precio]="","",IF([@Precio]<300,"$100-300",IF([@Precio]<600,"$300-600",IF([@Precio]<1000,"$600-1000","$1000+")))) | E41: Disponible | G41: No
...

Sheet Ingresos por Sucursal y Mes
A1: Ingresos por Sucursal y Mes
A2: Año a analizar: | B2: 2026 | D2: Cambia el año en B2 para ver otro periodo. Los valores usan la fecha de registro de cada mesa. Se actualiza solo al agregar mesas o productos.
A4: Sucursal | B4: =DATE($B$2,1,1) | C4: =DATE($B$2,2,1) | D4: =DATE($B$2,3,1) | E4: =DATE($B$2,4,1) | F4: =DATE($B$2,5,1) | G4: =DATE($B$2,6,1) | H4: =DATE($B$2,7,1) | I4: =DATE($B$2,8,1) | J4: =DATE($B$2,9,1) | K4: =DATE($B$2,10,1) | L4: =DATE($B$2,11,1) | M4: =DATE($B$2,12,1) | N4: Total
A5: Garita | B5: =SUMPRODUCT((Mesas[Sucursal]=$A5)*(YEAR(Mesas[Fecha de registro])=$B$2)*(MONTH(Mesas[Fecha de registro])=MONTH(B$4))*Mesas[Ingreso real generado]) | C5: =SUMPRODUCT((Mesas[Sucursal]=$A5)*(YEAR(Mesas[Fecha de registro])=$B$2)*(MONTH(Mesas[Fecha de registro])=MONTH(C$4))*Mesas[Ingreso real generado]) | D5: =SUMPRODUCT((Mesas[Sucursal]=$A5)*(YEAR(Mesas[Fecha de registro])=$B$2)*(MONTH(Mesas[Fecha de registro])=MONTH(D$4))*Mesas[Ingreso real generado]) | E5: =SUMPRODUCT((Mesas[Sucursal]=$A5)*(YEAR(Mesas[Fecha de registro])=$B$2)*(MONTH(Mesas[Fecha de registro])=MONTH(E$4))*Mesas[Ingreso real generado]) | F5: =SUMPRODUCT((Mesas[Sucursal]=$A5)*(YEAR(Mesas[Fecha de registro])=$B$2)*(MONTH(Mesas[Fecha de registro])=MONTH(F$4))*Mesas[Ingreso real generado]) | G5: =SUMPRODUCT((Mesas[Sucursal]=$A5)*(YEAR(Mesas[Fecha de registro])=$B$2)*(MONTH(Mesas[Fecha de registro])=MONTH(G$4))*Mesas[Ingreso real generado]) | H5: =SUMPRODUCT((Mesas[Sucursal]=$A5)*(YEAR(Mesas[Fecha de registro])=$B$2)*(MONTH(Mesas[Fecha de registro])=MONTH(H$4))*Mesas[Ingreso real generado]) | I5: =SUMPRODUCT((Mesas[Sucursal]=$A5)*(YEAR(Mesas[Fecha de registro])=$B$2)*(MONTH(Mesas[Fecha de registro])=MONTH(I$4))*Mesas[Ingreso real generado]) | ... M5: =SUMPRODUCT((Mesas[Sucursal]=$A5)*(YEAR(Mesas[Fecha de registro])=$B$2)*(MONTH(Mesas[Fecha de registro])=MONTH(M$4))*Mesas[Ingreso real generado]) | N5: =SUM(B5:M5)
A6: Buen Tono | B6: =SUMPRODUCT((Mesas[Sucursal]=$A6)*(YEAR(Mesas[Fecha de registro])=$B$2)*(MONTH(Mesas[Fecha de registro])=MONTH(B$4))*Mesas[Ingreso real generado]) | C6: =SUMPRODUCT((Mesas[Sucursal]=$A6)*(YEAR(Mesas[Fecha de registro])=$B$2)*(MONTH(Mesas[Fecha de registro])=MONTH(C$4))*Mesas[Ingreso real generado]) | D6: =SUMPRODUCT((Mesas[Sucursal]=$A6)*(YEAR(Mesas[Fecha de registro])=$B$2)*(MONTH(Mesas[Fecha de registro])=MONTH(D$4))*Mesas[Ingreso real generado]) | E6: =SUMPRODUCT((Mesas[Sucursal]=$A6)*(YEAR(Mesas[Fecha de registro])=$B$2)*(MONTH(Mesas[Fecha de registro])=MONTH(E$4))*Mesas[Ingreso real generado]) | F6: =SUMPRODUCT((Mesas[Sucursal]=$A6)*(YEAR(Mesas[Fecha de registro])=$B$2)*(MONTH(Mesas[Fecha de registro])=MONTH(F$4))*Mesas[Ingreso real generado]) | G6: =SUMPRODUCT((Mesas[Sucursal]=$A6)*(YEAR(Mesas[Fecha de registro])=$B$2)*(MONTH(Mesas[Fecha de registro])=MONTH(G$4))*Mesas[Ingreso real generado]) | H6: =SUMPRODUCT((Mesas[Sucursal]=$A6)*(YEAR(Mesas[Fecha de registro])=$B$2)*(MONTH(Mesas[Fecha de registro])=MONTH(H$4))*Mesas[Ingreso real generado]) | I6: =SUMPRODUCT((Mesas[Sucursal]=$A6)*(YEAR(Mesas[Fecha de registro])=$B$2)*(MONTH(Mesas[Fecha de registro])=MONTH(I$4))*Mesas[Ingreso real generado]) | ... M6: =SUMPRODUCT((Mesas[Sucursal]=$A6)*(YEAR(Mesas[Fecha de registro])=$B$2)*(MONTH(Mesas[Fecha de registro])=MONTH(M$4))*Mesas[Ingreso real generado]) | N6: =SUM(B6:M6)
A7: La Gracia | B7: =SUMPRODUCT((Mesas[Sucursal]=$A7)*(YEAR(Mesas[Fecha de registro])=$B$2)*(MONTH(Mesas[Fecha de registro])=MONTH(B$4))*Mesas[Ingreso real generado]) | C7: =SUMPRODUCT((Mesas[Sucursal]=$A7)*(YEAR(Mesas[Fecha de registro])=$B$2)*(MONTH(Mesas[Fecha de registro])=MONTH(C$4))*Mesas[Ingreso real generado]) | D7: =SUMPRODUCT((Mesas[Sucursal]=$A7)*(YEAR(Mesas[Fecha de registro])=$B$2)*(MONTH(Mesas[Fecha de registro])=MONTH(D$4))*Mesas[Ingreso real generado]) | E7: =SUMPRODUCT((Mesas[Sucursal]=$A7)*(YEAR(Mesas[Fecha de registro])=$B$2)*(MONTH(Mesas[Fecha de registro])=MONTH(E$4))*Mesas[Ingreso real generado]) | F7: =SUMPRODUCT((Mesas[Sucursal]=$A7)*(YEAR(Mesas[Fecha de registro])=$B$2)*(MONTH(Mesas[Fecha de registro])=MONTH(F$4))*Mesas[Ingreso real generado]) | G7: =SUMPRODUCT((Mesas[Sucursal]=$A7)*(YEAR(Mesas[Fecha de registro])=$B$2)*(MONTH(Mesas[Fecha de registro])=MONTH(G$4))*Mesas[Ingreso real generado]) | H7: =SUMPRODUCT((Mesas[Sucursal]=$A7)*(YEAR(Mesas[Fecha de registro])=$B$2)*(MONTH(Mesas[Fecha de registro])=MONTH(H$4))*Mesas[Ingreso real generado]) | I7: =SUMPRODUCT((Mesas[Sucursal]=$A7)*(YEAR(Mesas[Fecha de registro])=$B$2)*(MONTH(Mesas[Fecha de registro])=MONTH(I$4))*Mesas[Ingreso real generado]) | ... M7: =SUMPRODUCT((Mesas[Sucursal]=$A7)*(YEAR(Mesas[Fecha de registro])=$B$2)*(MONTH(Mesas[Fecha de registro])=MONTH(M$4))*Mesas[Ingreso real generado]) | N7: =SUM(B7:M7)
A8: San Borja | B8: =SUMPRODUCT((Mesas[Sucursal]=$A8)*(YEAR(Mesas[Fecha de registro])=$B$2)*(MONTH(Mesas[Fecha de registro])=MONTH(B$4))*Mesas[Ingreso real generado]) | C8: =SUMPRODUCT((Mesas[Sucursal]=$A8)*(YEAR(Mesas[Fecha de registro])=$B$2)*(MONTH(Mesas[Fecha de registro])=MONTH(C$4))*Mesas[Ingreso real generado]) | D8: =SUMPRODUCT((Mesas[Sucursal]=$A8)*(YEAR(Mesas[Fecha de registro])=$B$2)*(MONTH(Mesas[Fecha de registro])=MONTH(D$4))*Mesas[Ingreso real generado]) | E8: =SUMPRODUCT((Mesas[Sucursal]=$A8)*(YEAR(Mesas[Fecha de registro])=$B$2)*(MONTH(Mesas[Fecha de registro])=MONTH(E$4))*Mesas[Ingreso real generado]) | F8: =SUMPRODUCT((Mesas[Sucursal]=$A8)*(YEAR(Mesas[Fecha de registro])=$B$2)*(MONTH(Mesas[Fecha de registro])=MONTH(F$4))*Mesas[Ingreso real generado]) | G8: =SUMPRODUCT((Mesas[Sucursal]=$A8)*(YEAR(Mesas[Fecha de registro])=$B$2)*(MONTH(Mesas[Fecha de registro])=MONTH(G$4))*Mesas[Ingreso real generado]) | H8: =SUMPRODUCT((Mesas[Sucursal]=$A8)*(YEAR(Mesas[Fecha de registro])=$B$2)*(MONTH(Mesas[Fecha de registro])=MONTH(H$4))*Mesas[Ingreso real generado]) | I8: =SUMPRODUCT((Mesas[Sucursal]=$A8)*(YEAR(Mesas[Fecha de registro])=$B$2)*(MONTH(Mesas[Fecha de registro])=MONTH(I$4))*Mesas[Ingreso real generado]) | ... M8: =SUMPRODUCT((Mesas[Sucursal]=$A8)*(YEAR(Mesas[Fecha de registro])=$B$2)*(MONTH(Mesas[Fecha de registro])=MONTH(M$4))*Mesas[Ingreso real generado]) | N8: =SUM(B8:M8)
A9: Total | B9: =SUM(B5:B8) | C9: =SUM(C5:C8) | D9: =SUM(D5:D8) | E9: =SUM(E5:E8) | F9: =SUM(F5:F8) | G9: =SUM(G5:G8) | H9: =SUM(H5:H8) | I9: =SUM(I5:I8) | ... N9: =SUM(N5:N8)

Sheet KPIs Operativos
A1: KPIs Operativos
A2: Todos los KPIs se calculan automáticamente desde 'Mesas Registradas' y 'Detalle de Productos por Mesa'.
A4: Métricas globales
A5: Ticket promedio por mesa (ingreso real) | B5: =IFERROR(AVERAGE(Mesas[Ingreso real generado]),0)
A6: Ticket promedio ponderado (ingreso total / # mesas con ingreso) | B6: =IFERROR(SUM(Mesas[Ingreso real generado])/COUNTIF(Mesas[Ingreso real generado],">0"),0)
A7: Ingreso total generado (todas las mesas) | B7: =SUM(Mesas[Ingreso real generado])
A8: Tasa de conversión global (productos vendidos / productos en lista) | B8: =IFERROR(SUM(Mesas[# de productos vendidos])/SUM(Mesas[# de productos en la lista]),0)
A9: # total de mesas registradas | B9: =COUNTA(Mesas[ID de mesa])
A10: # de mesas cerradas | B10: =COUNT(Mesas[Fecha de cierre de la mesa])
A11: # de mesas activas (sin fecha de cierre) | B11: =COUNTA(Mesas[ID de mesa])-COUNT(Mesas[Fecha de cierre de la mesa])
A12: Tiempo promedio entre registro y cierre (días) | B12: =IFERROR(SUMPRODUCT((Mesas[Fecha de cierre de la mesa]<>"")*(Mesas[Fecha de cierre de la mesa]-Mesas[Fecha de registro]))/COUNT(Mesas[Fecha de cierre de la mesa]),0)
A15: Ventas por rango de precio
A16: Rango | B16: # vendidos | C16: Ingreso | D16: % del ingreso total
A17: $100-300 | B17: =COUNTIFS(Productos[Rango de precio],$A17,Productos[Estado],"Vendido") | C17: =SUMIFS(Productos[Precio],Productos[Rango de precio],$A17,Productos[Estado],"Vendido") | D17: =IFERROR(C17/SUM($C$17:$C$20),0)
A18: $300-600 | B18: =COUNTIFS(Productos[Rango de precio],$A18,Productos[Estado],"Vendido") | C18: =SUMIFS(Productos[Precio],Productos[Rango de precio],$A18,Productos[Estado],"Vendido") | D18: =IFERROR(C18/SUM($C$17:$C$20),0)
A19: $600-1000 | B19: =COUNTIFS(Productos[Rango de precio],$A19,Productos[Estado],"Vendido") | C19: =SUMIFS(Productos[Precio],Productos[Rango de precio],$A19,Productos[Estado],"Vendido") | D19: =IFERROR(C19/SUM($C$17:$C$20),0)
A20: $1000+ | B20: =COUNTIFS(Productos[Rango de precio],$A20,Productos[Estado],"Vendido") | C20: =SUMIFS(Productos[Precio],Productos[Rango de precio],$A20,Productos[Estado],"Vendido") | D20: =IFERROR(C20/SUM($C$17:$C$20),0)
A22: Rango más vendido (por ingreso) | B22: =IFERROR(INDEX($A$17:$A$20,MATCH(MAX($C$17:$C$20),$C$17:$C$20,0)),"—")
A23: Rango más vendido (por # unidades) | B23: =IFERROR(INDEX($A$17:$A$20,MATCH(MAX($B$17:$B$20),$B$17:$B$20,0)),"—")
A26: Desempeño por sucursal
A27: Sucursal | B27: # mesas | C27: # productos vendidos | D27: Ingreso total | E27: Tasa conversión
A28: Garita | B28: =COUNTIF(Mesas[Sucursal],$A28) | C28: =SUMIF(Mesas[Sucursal],$A28,Mesas[# de productos vendidos]) | D28: =SUMIF(Mesas[Sucursal],$A28,Mesas[Ingreso real generado]) | E28: =IFERROR(SUMIF(Mesas[Sucursal],$A28,Mesas[# de productos vendidos])/SUMIF(Mesas[Sucursal],$A28,Mesas[# de productos en la lista]),0)
A29: Buen Tono | B29: =COUNTIF(Mesas[Sucursal],$A29) | C29: =SUMIF(Mesas[Sucursal],$A29,Mesas[# de productos vendidos]) | D29: =SUMIF(Mesas[Sucursal],$A29,Mesas[Ingreso real generado]) | E29: =IFERROR(SUMIF(Mesas[Sucursal],$A29,Mesas[# de productos vendidos])/SUMIF(Mesas[Sucursal],$A29,Mesas[# de productos en la lista]),0)
A30: La Gracia | B30: =COUNTIF(Mesas[Sucursal],$A30) | C30: =SUMIF(Mesas[Sucursal],$A30,Mesas[# de productos vendidos]) | D30: =SUMIF(Mesas[Sucursal],$A30,Mesas[Ingreso real generado]) | E30: =IFERROR(SUMIF(Mesas[Sucursal],$A30,Mesas[# de productos vendidos])/SUMIF(Mesas[Sucursal],$A30,Mesas[# de productos en la lista]),0)
A31: San Borja | B31: =COUNTIF(Mesas[Sucursal],$A31) | C31: =SUMIF(Mesas[Sucursal],$A31,Mesas[# de productos vendidos]) | D31: =SUMIF(Mesas[Sucursal],$A31,Mesas[Ingreso real generado]) | E31: =IFERROR(SUMIF(Mesas[Sucursal],$A31,Mesas[# de productos vendidos])/SUMIF(Mesas[Sucursal],$A31,Mesas[# de productos en la lista]),0)
A33: Sucursal con mayor ingreso | B33: =IFERROR(INDEX($A$28:$A$31,MATCH(MAX($D$28:$D$31),$D$28:$D$31,0)),"—")
A34: Sucursal con menor ingreso | B34: =IFERROR(INDEX($A$28:$A$31,MATCH(MIN($D$28:$D$31),$D$28:$D$31,0)),"—")
A35: Sucursal con más productos vendidos | B35: =IFERROR(INDEX($A$28:$A$31,MATCH(MAX($C$28:$C$31),$C$28:$C$31,0)),"—")
A36: Sucursal con menos productos vendidos | B36: =IFERROR(INDEX($A$28:$A$31,MATCH(MIN($C$28:$C$31),$C$28:$C$31,0)),"—")
A39: Mesas activas por sucursal y mes
A40: Una mesa se considera activa en un mes si fue registrada antes o durante el mes y aún no había sido cerrada al final de ese mes. Se usa el año definido en 'Ingresos por Sucursal y Mes'.
A41: Sucursal | B41: =DATE('Ingresos por Sucursal y Mes'!$B$2,1,1) | C41: =DATE('Ingresos por Sucursal y Mes'!$B$2,2,1) | D41: =DATE('Ingresos por Sucursal y Mes'!$B$2,3,1) | E41: =DATE('Ingresos por Sucursal y Mes'!$B$2,4,1) | F41: =DATE('Ingresos por Sucursal y Mes'!$B$2,5,1) | G41: =DATE('Ingresos por Sucursal y Mes'!$B$2,6,1) | H41: =DATE('Ingresos por Sucursal y Mes'!$B$2,7,1) | I41: =DATE('Ingresos por Sucursal y Mes'!$B$2,8,1) | J41: =DATE('Ingresos por Sucursal y Mes'!$B$2,9,1) | K41: =DATE('Ingresos por Sucursal y Mes'!$B$2,10,1) | L41: =DATE('Ingresos por Sucursal y Mes'!$B$2,11,1) | M41: =DATE('Ingresos por Sucursal y Mes'!$B$2,12,1) | N41: Promedio
A42: Garita | B42: =SUMPRODUCT((Mesas[Sucursal]=$A42)*(Mesas[Fecha de registro]<>"")*(Mesas[Fecha de registro]<=EOMONTH(B$41,0))*((Mesas[Fecha de cierre de la mesa]="")+(Mesas[Fecha de cierre de la mesa]>EOMONTH(B$41,0))>0)) | C42: =SUMPRODUCT((Mesas[Sucursal]=$A42)*(Mesas[Fecha de registro]<>"")*(Mesas[Fecha de registro]<=EOMONTH(C$41,0))*((Mesas[Fecha de cierre de la mesa]="")+(Mesas[Fecha de cierre de la mesa]>EOMONTH(C$41,0))>0)) | D42: =SUMPRODUCT((Mesas[Sucursal]=$A42)*(Mesas[Fecha de registro]<>"")*(Mesas[Fecha de registro]<=EOMONTH(D$41,0))*((Mesas[Fecha de cierre de la mesa]="")+(Mesas[Fecha de cierre de la mesa]>EOMONTH(D$41,0))>0)) | E42: =SUMPRODUCT((Mesas[Sucursal]=$A42)*(Mesas[Fecha de registro]<>"")*(Mesas[Fecha de registro]<=EOMONTH(E$41,0))*((Mesas[Fecha de cierre de la mesa]="")+(Mesas[Fecha de cierre de la mesa]>EOMONTH(E$41,0))>0)) | F42: =SUMPRODUCT((Mesas[Sucursal]=$A42)*(Mesas[Fecha de registro]<>"")*(Mesas[Fecha de registro]<=EOMONTH(F$41,0))*((Mesas[Fecha de cierre de la mesa]="")+(Mesas[Fecha de cierre de la mesa]>EOMONTH(F$41,0))>0)) | G42: =SUMPRODUCT((Mesas[Sucursal]=$A42)*(Mesas[Fecha de registro]<>"")*(Mesas[Fecha de registro]<=EOMONTH(G$41,0))*((Mesas[Fecha de cierre de la mesa]="")+(Mesas[Fecha de cierre de la mesa]>EOMONTH(G$41,0))>0)) | H42: =SUMPRODUCT((Mesas[Sucursal]=$A42)*(Mesas[Fecha de registro]<>"")*(Mesas[Fecha de registro]<=EOMONTH(H$41,0))*((Mesas[Fecha de cierre de la mesa]="")+(Mesas[Fecha de cierre de la mesa]>EOMONTH(H$41,0))>0)) | I42: =SUMPRODUCT((Mesas[Sucursal]=$A42)*(Mesas[Fecha de registro]<>"")*(Mesas[Fecha de registro]<=EOMONTH(I$41,0))*((Mesas[Fecha de cierre de la mesa]="")+(Mesas[Fecha de cierre de la mesa]>EOMONTH(I$41,0))>0)) | ... M42: =SUMPRODUCT((Mesas[Sucursal]=$A42)*(Mesas[Fecha de registro]<>"")*(Mesas[Fecha de registro]<=EOMONTH(M$41,0))*((Mesas[Fecha de cierre de la mesa]="")+(Mesas[Fecha de cierre de la mesa]>EOMONTH(M$41,0))>0)) | N42: =AVERAGE(B42:M42)
A43: Buen Tono | B43: =SUMPRODUCT((Mesas[Sucursal]=$A43)*(Mesas[Fecha de registro]<>"")*(Mesas[Fecha de registro]<=EOMONTH(B$41,0))*((Mesas[Fecha de cierre de la mesa]="")+(Mesas[Fecha de cierre de la mesa]>EOMONTH(B$41,0))>0)) | C43: =SUMPRODUCT((Mesas[Sucursal]=$A43)*(Mesas[Fecha de registro]<>"")*(Mesas[Fecha de registro]<=EOMONTH(C$41,0))*((Mesas[Fecha de cierre de la mesa]="")+(Mesas[Fecha de cierre de la mesa]>EOMONTH(C$41,0))>0)) | D43: =SUMPRODUCT((Mesas[Sucursal]=$A43)*(Mesas[Fecha de registro]<>"")*(Mesas[Fecha de registro]<=EOMONTH(D$41,0))*((Mesas[Fecha de cierre de la mesa]="")+(Mesas[Fecha de cierre de la mesa]>EOMONTH(D$41,0))>0)) | E43: =SUMPRODUCT((Mesas[Sucursal]=$A43)*(Mesas[Fecha de registro]<>"")*(Mesas[Fecha de registro]<=EOMONTH(E$41,0))*((Mesas[Fecha de cierre de la mesa]="")+(Mesas[Fecha de cierre de la mesa]>EOMONTH(E$41,0))>0)) | F43: =SUMPRODUCT((Mesas[Sucursal]=$A43)*(Mesas[Fecha de registro]<>"")*(Mesas[Fecha de registro]<=EOMONTH(F$41,0))*((Mesas[Fecha de cierre de la mesa]="")+(Mesas[Fecha de cierre de la mesa]>EOMONTH(F$41,0))>0)) | G43: =SUMPRODUCT((Mesas[Sucursal]=$A43)*(Mesas[Fecha de registro]<>"")*(Mesas[Fecha de registro]<=EOMONTH(G$41,0))*((Mesas[Fecha de cierre de la mesa]="")+(Mesas[Fecha de cierre de la mesa]>EOMONTH(G$41,0))>0)) | H43: =SUMPRODUCT((Mesas[Sucursal]=$A43)*(Mesas[Fecha de registro]<>"")*(Mesas[Fecha de registro]<=EOMONTH(H$41,0))*((Mesas[Fecha de cierre de la mesa]="")+(Mesas[Fecha de cierre de la mesa]>EOMONTH(H$41,0))>0)) | I43: =SUMPRODUCT((Mesas[Sucursal]=$A43)*(Mesas[Fecha de registro]<>"")*(Mesas[Fecha de registro]<=EOMONTH(I$41,0))*((Mesas[Fecha de cierre de la mesa]="")+(Mesas[Fecha de cierre de la mesa]>EOMONTH(I$41,0))>0)) | ... M43: =SUMPRODUCT((Mesas[Sucursal]=$A43)*(Mesas[Fecha de registro]<>"")*(Mesas[Fecha de registro]<=EOMONTH(M$41,0))*((Mesas[Fecha de cierre de la mesa]="")+(Mesas[Fecha de cierre de la mesa]>EOMONTH(M$41,0))>0)) | N43: =AVERAGE(B43:M43)
A44: La Gracia | B44: =SUMPRODUCT((Mesas[Sucursal]=$A44)*(Mesas[Fecha de registro]<>"")*(Mesas[Fecha de registro]<=EOMONTH(B$41,0))*((Mesas[Fecha de cierre de la mesa]="")+(Mesas[Fecha de cierre de la mesa]>EOMONTH(B$41,0))>0)) | C44: =SUMPRODUCT((Mesas[Sucursal]=$A44)*(Mesas[Fecha de registro]<>"")*(Mesas[Fecha de registro]<=EOMONTH(C$41,0))*((Mesas[Fecha de cierre de la mesa]="")+(Mesas[Fecha de cierre de la mesa]>EOMONTH(C$41,0))>0)) | D44: =SUMPRODUCT((Mesas[Sucursal]=$A44)*(Mesas[Fecha de registro]<>"")*(Mesas[Fecha de registro]<=EOMONTH(D$41,0))*((Mesas[Fecha de cierre de la mesa]="")+(Mesas[Fecha de cierre de la mesa]>EOMONTH(D$41,0))>0)) | E44: =SUMPRODUCT((Mesas[Sucursal]=$A44)*(Mesas[Fecha de registro]<>"")*(Mesas[Fecha de registro]<=EOMONTH(E$41,0))*((Mesas[Fecha de cierre de la mesa]="")+(Mesas[Fecha de cierre de la mesa]>EOMONTH(E$41,0))>0)) | F44: =SUMPRODUCT((Mesas[Sucursal]=$A44)*(Mesas[Fecha de registro]<>"")*(Mesas[Fecha de registro]<=EOMONTH(F$41,0))*((Mesas[Fecha de cierre de la mesa]="")+(Mesas[Fecha de cierre de la mesa]>EOMONTH(F$41,0))>0)) | G44: =SUMPRODUCT((Mesas[Sucursal]=$A44)*(Mesas[Fecha de registro]<>"")*(Mesas[Fecha de registro]<=EOMONTH(G$41,0))*((Mesas[Fecha de cierre de la mesa]="")+(Mesas[Fecha de cierre de la mesa]>EOMONTH(G$41,0))>0)) | H44: =SUMPRODUCT((Mesas[Sucursal]=$A44)*(Mesas[Fecha de registro]<>"")*(Mesas[Fecha de registro]<=EOMONTH(H$41,0))*((Mesas[Fecha de cierre de la mesa]="")+(Mesas[Fecha de cierre de la mesa]>EOMONTH(H$41,0))>0)) | I44: =SUMPRODUCT((Mesas[Sucursal]=$A44)*(Mesas[Fecha de registro]<>"")*(Mesas[Fecha de registro]<=EOMONTH(I$41,0))*((Mesas[Fecha de cierre de la mesa]="")+(Mesas[Fecha de cierre de la mesa]>EOMONTH(I$41,0))>0)) | ... M44: =SUMPRODUCT((Mesas[Sucursal]=$A44)*(Mesas[Fecha de registro]<>"")*(Mesas[Fecha de registro]<=EOMONTH(M$41,0))*((Mesas[Fecha de cierre de la mesa]="")+(Mesas[Fecha de cierre de la mesa]>EOMONTH(M$41,0))>0)) | N44: =AVERAGE(B44:M44)
A45: San Borja | B45: =SUMPRODUCT((Mesas[Sucursal]=$A45)*(Mesas[Fecha de registro]<>"")*(Mesas[Fecha de registro]<=EOMONTH(B$41,0))*((Mesas[Fecha de cierre de la mesa]="")+(Mesas[Fecha de cierre de la mesa]>EOMONTH(B$41,0))>0)) | C45: =SUMPRODUCT((Mesas[Sucursal]=$A45)*(Mesas[Fecha de registro]<>"")*(Mesas[Fecha de registro]<=EOMONTH(C$41,0))*((Mesas[Fecha de cierre de la mesa]="")+(Mesas[Fecha de cierre de la mesa]>EOMONTH(C$41,0))>0)) | D45: =SUMPRODUCT((Mesas[Sucursal]=$A45)*(Mesas[Fecha de registro]<>"")*(Mesas[Fecha de registro]<=EOMONTH(D$41,0))*((Mesas[Fecha de cierre de la mesa]="")+(Mesas[Fecha de cierre de la mesa]>EOMONTH(D$41,0))>0)) | E45: =SUMPRODUCT((Mesas[Sucursal]=$A45)*(Mesas[Fecha de registro]<>"")*(Mesas[Fecha de registro]<=EOMONTH(E$41,0))*((Mesas[Fecha de cierre de la mesa]="")+(Mesas[Fecha de cierre de la mesa]>EOMONTH(E$41,0))>0)) | F45: =SUMPRODUCT((Mesas[Sucursal]=$A45)*(Mesas[Fecha de registro]<>"")*(Mesas[Fecha de registro]<=EOMONTH(F$41,0))*((Mesas[Fecha de cierre de la mesa]="")+(Mesas[Fecha de cierre de la mesa]>EOMONTH(F$41,0))>0)) | G45: =SUMPRODUCT((Mesas[Sucursal]=$A45)*(Mesas[Fecha de registro]<>"")*(Mesas[Fecha de registro]<=EOMONTH(G$41,0))*((Mesas[Fecha de cierre de la mesa]="")+(Mesas[Fecha de cierre de la mesa]>EOMONTH(G$41,0))>0)) | H45: =SUMPRODUCT((Mesas[Sucursal]=$A45)*(Mesas[Fecha de registro]<>"")*(Mesas[Fecha de registro]<=EOMONTH(H$41,0))*((Mesas[Fecha de cierre de la mesa]="")+(Mesas[Fecha de cierre de la mesa]>EOMONTH(H$41,0))>0)) | I45: =SUMPRODUCT((Mesas[Sucursal]=$A45)*(Mesas[Fecha de registro]<>"")*(Mesas[Fecha de registro]<=EOMONTH(I$41,0))*((Mesas[Fecha de cierre de la mesa]="")+(Mesas[Fecha de cierre de la mesa]>EOMONTH(I$41,0))>0)) | ... M45: =SUMPRODUCT((Mesas[Sucursal]=$A45)*(Mesas[Fecha de registro]<>"")*(Mesas[Fecha de registro]<=EOMONTH(M$41,0))*((Mesas[Fecha de cierre de la mesa]="")+(Mesas[Fecha de cierre de la mesa]>EOMONTH(M$41,0))>0)) | N45: =AVERAGE(B45:M45)
A46: Promedio mesas activas simultáneas (global) | B46: =AVERAGE(B42:M45)

Sheet Escalabilidad y Capacidad
A1: Escalabilidad y Capacidad
A2: Ajusta los parámetros en las celdas amarillas para simular escenarios. La capacidad se calcula como (empleados × horas/semana) ÷ horas de atención por mesa/semana. En temporada alta (nov-ene) la demanda se multiplica por el factor definido en B7.
A4: Parámetros globales (editables)
A5: Empleados por sucursal (default) | B5: 3
A6: Horas laborables por empleado por semana | B6: 40
A7: Horas de atención por mesa por semana | B7: 4
A8: Multiplicador demanda temporada alta | B8: 1.5
A11: Capacidad por sucursal
A12: Sucursal | B12: Empleados | C12: Horas/semana totales | D12: Capacidad mesas simultáneas (temporada baja) | E12: Capacidad mesas simultáneas (temporada alta) | F12: Mesas activas actualmente
A13: Garita | B13: =$B$5 | C13: =B13*$B$6 | D13: =IFERROR(C13/$B$7,0) | E13: =D13 | F13: =SUMPRODUCT((Mesas[Sucursal]=$A13)*(Mesas[Fecha de registro]<>"")*(Mesas[Fecha de cierre de la mesa]=""))
A14: Buen Tono | B14: =$B$5 | C14: =B14*$B$6 | D14: =IFERROR(C14/$B$7,0) | E14: =D14 | F14: =SUMPRODUCT((Mesas[Sucursal]=$A14)*(Mesas[Fecha de registro]<>"")*(Mesas[Fecha de cierre de la mesa]=""))
A15: La Gracia | B15: =$B$5 | C15: =B15*$B$6 | D15: =IFERROR(C15/$B$7,0) | E15: =D15 | F15: =SUMPRODUCT((Mesas[Sucursal]=$A15)*(Mesas[Fecha de registro]<>"")*(Mesas[Fecha de cierre de la mesa]=""))
A16: San Borja | B16: =$B$5 | C16: =B16*$B$6 | D16: =IFERROR(C16/$B$7,0) | E16: =D16 | F16: =SUMPRODUCT((Mesas[Sucursal]=$A16)*(Mesas[Fecha de registro]<>"")*(Mesas[Fecha de cierre de la mesa]=""))
A17: Total / Promedio | B17: =SUM(B13:B16) | C17: =SUM(C13:C16) | D17: =SUM(D13:D16) | E17: =SUM(E13:E16) | F17: =SUM(F13:F16)
A20: Utilización y saturación
A21: Sucursal | B21: Mesas activas | C21: Capacidad | D21: % utilización actual | E21: % utilización proyectada temporada alta | F21: Semáforo
A22: Garita | B22: =F13 | C22: =D13 | D22: =IFERROR(B22/C22,0) | E22: =IFERROR(B22*$B$8/C22,0) | F22: =IF(E22>=1,"SATURADO",IF(E22>=0.8,"RIESGO",IF(E22>=0.5,"OK","HOLGURA")))
A23: Buen Tono | B23: =F14 | C23: =D14 | D23: =IFERROR(B23/C23,0) | E23: =IFERROR(B23*$B$8/C23,0) | F23: =IF(E23>=1,"SATURADO",IF(E23>=0.8,"RIESGO",IF(E23>=0.5,"OK","HOLGURA")))
A24: La Gracia | B24: =F15 | C24: =D15 | D24: =IFERROR(B24/C24,0) | E24: =IFERROR(B24*$B$8/C24,0) | F24: =IF(E24>=1,"SATURADO",IF(E24>=0.8,"RIESGO",IF(E24>=0.5,"OK","HOLGURA")))
A25: San Borja | B25: =F16 | C25: =D16 | D25: =IFERROR(B25/C25,0) | E25: =IFERROR(B25*$B$8/C25,0) | F25: =IF(E25>=1,"SATURADO",IF(E25>=0.8,"RIESGO",IF(E25>=0.5,"OK","HOLGURA")))
